Workbook

Sheet Guidleline
A1: Guideline to make and understand Unit Test Case
A3: 1. Overview
A4: - In the template, Unit test cases are based on functions. Each sheet presents test cases for one function.
A5: - Cover: General information of the project and Unit Test cases
A6: - FunctionList: The list of Classes and Functions in the document. + To control that the number of Unit TC meets customer's requirement or the norm, user should fill value for 'Normal number of Test cases/KLOC'.
A7: + Click on Function link to open the related Test cases of the function. Note: You should create new Function sheet before creating the link
A8: - Test Report: provive the overview results of Functions Unit test: Test coverage, Test successful coverage (Summary, for normal/abnormal/boundary cases)
A9: Note: Should check the formula of "Sub Total" if you add more functions
A11: 2. Content in Test function sheet
A12: 2.1 Combination of test cases.
A13: - To verify that number of Unit TC meets customer's requirement or not. User has to fill number LOC of tested function and fill value of 'Normal number test cases/KLOC' item in FunctionList sheet, which is required by customer or normal value. The number of lacked TC is shown in 'Lack of test cases' item.
A14: - If the number of Unit TC does not meet the requirement, creator should explain the reasons.
... A47: - Test requirement: Brief description about requirements which are tested in this function, it is not mandatory.

Sheet Cover
A2: UNIT TEST CASE
A4: Project Name | B4: HappyProgramming Mentorship System | E4: Creator | F4: Nguyen Bao Trung
A5: Project Code | B5: HPMS | E5: Reviewer/Approver
A6: Document Code | B6: HPMS_MENTOR_UTC_v1.0 | E6: Issue Date | F6: 46313
E7: Version | F7: 1.0
A10: Record of change
A11: Effective Date | B11: Version | C11: Change Item | D11: *A,D,M | E11: Change description | F11: Reference
A12: 46313 | B12: 1.0 | C12: Mentor unit test template | D12: M | E12: Recreated the Mentor report using the Admin workbook layout. | F12: Unit_TestCase_Admin_HPMS.xlsx / Mentor unit test sources
A15: Execution status | B15: Test design, not an execution record. All result/date/defect fields are blank until each case is executed. Earlier suite totals do not prove these individual cases passed.

Sheet FunctionList
E2: UNIT TEST CASE LIST
A4: Project Name | E4: HappyProgramming Mentorship System - Mentor Role
A5: Project Code | E5: HPMS
A6: Normal number of Test cases/KLOC | E6: 100
A7: Test Environment Setup Description | E7: 1. Backend: Spring Boot 3.5 / Java 17, mvnw -o test (JUnit5 + Mockito) 2. Frontend: Vite + Vanilla JS, node --test 3. Database: SQL Server localhost,1433 (HappyProgramming) 4. Conditional integration tests gated by hpms.dashboard.integration / DB_PASSWORD
A10: No | B10: Requirement Name | C10: Class Name | D10: Function Name | E10: Function Code(Optional) | F10: Sheet Name | G10: Description | H10: Pre-Condition
A11: 1 | B11: Register as Mentor and submit CV / qualification certificates | C11: Mentor_Application | D11: See the per-case source map in the evidence document | E11: MTR_APPLICATION | F11: Mentor_Application | G11: SRS trace: UC15. UC15: active registered account and no pending application; required biography/experience/skills; PDF under 10 MB; application becomes PENDING and enters Staff review queue. | H11: Registered active account; no pending mentor application. Active skill exists; CV/certificates must be PDF files under 10 MB.
A12: 2 | B12: Publish availability and prevent conflicting slot reservations | C12: Availability_Schedule | D12: See the per-case source map in the evidence document | E12: MTR_AVAILABILITY | F12: Availability_Schedule | G12: SRS trace: No dedicated UC. SRS booking rules: validate Mentor availability, prevent overlapping bookings, reserve selected slots temporarily for 10 minutes, release expired/replaced holds, and recheck before confirmation. | H12: Authenticated active Mentor; valid future availability. Slot holds expire after 10 minutes and overlapping confirmed reservations are forbidden.
A13: 3 | B13: Manage profile, biography, experience, links and teaching skills | C13: Profile_Management | D13: See the per-case source map in the evidence document | E13: MTR_PROFILE | F13: Profile_Management | G13: SRS trace: UC13 / UC11. UC13: active authenticated Mentor edits profile; bio length 50–1,000 characters and avatar JPG/PNG under 5 MB. UC11: only active Staff-approved skills; at least one skill must remain selected. | H13: Authenticated active Mentor. Teaching-skill catalog is configured and only active skills can be selected.
A14: 4 | B14: Manage mentor service offerings and selected package price | C14: Package_Management | D14: See the per-case source map in the evidence document | E14: MTR_PACKAGES | F14: Package_Management | G14: SRS trace: No dedicated UC. SRS UC20 allows a Mentee to select an available package. Mentor package administration is an implemented feature; selection must preserve the chosen active offering and its price snapshot. | H14: Authenticated active Mentor with service-offering records; public selection is limited to active offerings.
A15: 5 | B15: View mentor request, notice, rating and earnings overview | C15: Dashboard_Overview | D15: See the per-case source map in the evidence document | E15: MTR_DASHBOARD | F15: Dashboard_Overview | G15: SRS trace: No dedicated UC. SRS Mentor overview: real-time net earnings, pending escrow, average rating, incoming requests and 48-hour response SLA. Dashboard itself has no dedicated UC number. | H15: Authenticated active Mentor; repository fixtures provide mentor-scoped request, notice, rating and earnings data.
A16: 6 | B16: View and accept or reject pending mentorship requests | C16: Request_Approval | D16: See the per-case source map in the evidence document | E16: MTR_REQUESTS | F16: Request_Approval | G16: SRS trace: UC26. UC26: only PENDING owned requests may be accepted/rejected within 48 hours; decision notifies Mentee. Acceptance unlocks payment only; it does not activate mentorship or create escrow before verified payment. | H16: Authenticated Mentor owns the request; monthly request is PENDING and within the 48-hour response window.
A17: 7 | B17: Access active mentorship workspace, messages and files | C17: Workspace_Management | D17: See the per-case source map in the evidence document | E17: MTR_WORKSPACE | F17: Workspace_Management | G17: SRS trace: UC32–33. SRS UC32–33: workspace/session access follows confirmed paid booking. Only authorized Mentee/Mentor members access messages, files and meeting links. | H17: Authenticated member of a paid active mentorship or confirmed booking; access is scoped to workspace membership.
A18: 8 | B18: Review wallet and request OTP-protected payout | C18: Wallet_Payout | D18: See the per-case source map in the evidence document | E18: MTR_WALLET | F18: Wallet_Payout | G18: SRS trace: No dedicated UC. No dedicated Mentor wallet/payout UC in supplied SRS. Project rules: verified mentor earnings are held seven days; only available unreserved balance can be requested; OTP and saved destination are required. Admin executes payout externally. | H18: Authenticated Mentor; verified earnings respect the seven-day hold; bank destination and valid OTP are required for withdrawal.
A19: 9 | B19: View net earnings, rating summary and mentee feedback | C19: Review_Feedback | D19: See the per-case source map in the evidence document | E19: MTR_REVIEWS | F19: Review_Feedback | G19: SRS trace: UC28 / UC35. UC28: show net revenue after commission, pending escrow and mentee feedback. UC35: Mentor views received ratings/comments. Only completed bookings can be rated; refunded/cancelled trial sessions are excluded from net earnings. | H19: Authenticated Mentor with active profile; reviews are eligible/published and feedback is limited to completed bookings.
A20: 10 | B20: N/A - Availability & Slot Management (BR-10/BR-11) | C20: MentorAvailabilityControllerTest | D20: createSlotReturnsCreated | E20: FUNC_MENTOR_AVAILABILITY | F20: 02_MentorAvailabilityCtrl | G20: create slot returns created | H20: Mentor authenticated; Spring context / mocked beans wired
A21: 11 | B21: N/A - Availability & Slot Management (BR-10/BR-11) | C21: MentorAvailabilityControllerTest | D21: createSlotRejectsMissingStart | E21: FUNC_MENTOR_AVAILABILITY | F21: 02_MentorAvailabilityCtrl | G21: create slot rejects missing start | H21: Mentor authenticated; Spring context / mocked beans wired
A22: 12 | B22: N/A - Availability & Slot Management (BR-10/BR-11) | C22: MentorAvailabilityControllerTest | D22: deleteSlotReturnsOk | E22: FUNC_MENTOR_AVAILABILITY | F22: 02_MentorAvailabilityCtrl | G22: delete slot returns ok | H22: Mentor authenticated; Spring context / mocked beans wired
... A182: 172 | B182: UC28 - Payout/bank API client (CSRF) | C182: mentorWalletService | D182: payout request fetches a CSRF token before posting bank details | E182: FUNC_MENTOR_WALLET | F182: 36_mentorWalletSvc | G182: payout request fetches a CSRF token before posting bank details | H182: Mentor route mounted; fetch/apiClient mocked

Sheet Test Report
A2: UNIT TEST REPORT
A4: Project Name | B4: HappyProgramming Mentorship System | D4: Creator | F4: Nguyen Bao Trung
A5: Project Code | B5: HPMS | D5: Reviewer/Approver
A6: Document Code | B6: HPMS_MENTOR_UTC_v1.0 | D6: Issue Date | F6: 46313
A7: Notes | B7: Untested cases remain blank. Result totals reflect recorded P/F/U execution states; U is included in Untested.
A11: No | B11: Function code | C11: Passed | D11: Failed | E11: Untested | F11: N | G11: A | H11: B | I11: Total Test Cases
A12: 1 | B12: =FunctionList!E11 -> MTR_APPLICATION | C12: =Mentor_Application!A7 -> 8 | D12: =Mentor_Application!C7 -> 0 | E12: =Mentor_Application!F7 -> 0 | F12: =Mentor_Application!L7 -> 0 | G12: =Mentor_Application!M7 -> 7 | H12: =Mentor_Application!N7 -> 1 | I12: =Mentor_Application!O7 -> 8
A13: 2 | B13: =FunctionList!E12 -> MTR_AVAILABILITY | C13: =Availability_Schedule!A7 -> 22 | D13: =Availability_Schedule!C7 -> 0 | E13: =Availability_Schedule!F7 -> 0 | F13: =Availability_Schedule!L7 -> 14 | G13: =Availability_Schedule!M7 -> 7 | H13: =Availability_Schedule!N7 -> 1 | I13: =Availability_Schedule!O7 -> 22
A14: 3 | B14: =FunctionList!E13 -> MTR_PROFILE | C14: =Profile_Management!A7 -> 35 | D14: =Profile_Management!C7 -> 0 | E14: =Profile_Management!F7 -> 1 | F14: =Profile_Management!L7 -> 22 | G14: =Profile_Management!M7 -> 9 | H14: =Profile_Management!N7 -> 5 | I14: =Profile_Management!O7 -> 36
A15: 4 | B15: =FunctionList!E14 -> MTR_PACKAGES | C15: =Package_Management!A7 -> 11 | D15: =Package_Management!C7 -> 0 | E15: =Package_Management!F7 -> 0 | F15: =Package_Management!L7 -> 7 | G15: =Package_Management!M7 -> 4 | H15: =Package_Management!N7 -> 0 | I15: =Package_Management!O7 -> 11
A16: 5 | B16: =FunctionList!E15 -> MTR_DASHBOARD | C16: =Dashboard_Overview!A7 -> 13 | D16: =Dashboard_Overview!C7 -> 0 | E16: =Dashboard_Overview!F7 -> 0 | F16: =Dashboard_Overview!L7 -> 10 | G16: =Dashboard_Overview!M7 -> 3 | H16: =Dashboard_Overview!N7 -> 0 | I16: =Dashboard_Overview!O7 -> 13
A17: 6 | B17: =FunctionList!E16 -> MTR_REQUESTS | C17: =Request_Approval!A7 -> 31 | D17: =Request_Approval!C7 -> 0 | E17: =Request_Approval!F7 -> 2 | F17: =Request_Approval!L7 -> 19 | G17: =Request_Approval!M7 -> 13 | H17: =Request_Approval!N7 -> 1 | I17: =Request_Approval!O7 -> 33
A18: 7 | B18: =FunctionList!E17 -> MTR_WORKSPACE | C18: =Workspace_Management!A7 -> 13 | D18: =Workspace_Management!C7 -> 0 | E18: =Workspace_Management!F7 -> 1 | F18: =Workspace_Management!L7 -> 10 | G18: =Workspace_Management!M7 -> 3 | H18: =Workspace_Management!N7 -> 1 | I18: =Workspace_Management!O7 -> 14
A19: 8 | B19: =FunctionList!E18 -> MTR_WALLET | C19: =Wallet_Payout!A7 -> 22 | D19: =Wallet_Payout!C7 -> 0 | E19: =Wallet_Payout!F7 -> 0 | F19: =Wallet_Payout!L7 -> 16 | G19: =Wallet_Payout!M7 -> 6 | H19: =Wallet_Payout!N7 -> 0 | I19: =Wallet_Payout!O7 -> 22
A20: 9 | B20: =FunctionList!E19 -> MTR_REVIEWS | C20: =Review_Feedback!A7 -> 13 | D20: =Review_Feedback!C7 -> 0 | E20: =Review_Feedback!F7 -> 0 | F20: =Review_Feedback!L7 -> 9 | G20: =Review_Feedback!M7 -> 1 | H20: =Review_Feedback!N7 -> 3 | I20: =Review_Feedback!O7 -> 13
B21: Sub total | C21: =SUM(C12:C20) -> 168 | D21: =SUM(D12:D20) -> 0 | E21: =SUM(E12:E20) -> 4 | F21: =SUM(F12:F20) -> 107 | G21: =SUM(G12:G20) -> 53 | H21: =SUM(H12:H20) -> 12 | I21: =SUM(I12:I20) -> 172
B22: Test coverage | D22: =IF(I21=0,0,SUM(C21:D21)/I21) -> 0.97674419
B23: Test successful coverage | D23: =IF(I21=0,0,C21/I21) -> 0.97674419
B24: Normal case | D24: =IF(I21=0,0,F21/I21) -> 0.62209302
B25: Abnormal case | D25: =IF(I21=0,0,G21/I21) -> 0.30813953
B26: Boundary case | D26: =IF(I21=0,0,H21/I21) -> 0.069767442
O30: Result | P30: Count | Q30: Percent
O31: Passed | P31: =C21 -> 168 | Q31: =P31/SUM($P$31:$P$33) -> 0.97674419
O32: Failed | P32: =D21 -> 0 | Q32: =P32/SUM($P$31:$P$33) -> 0
O33: Untested | P33: =E21 -> 4 | Q33: =P33/SUM($P$31:$P$33) -> 0.023255814
O36: Test Type | P36: Count | Q36: Percent
O37: N | P37: =F21 -> 107 | Q37: =P37/SUM($P$37:$P$39) -> 0.62209302
O38: A | P38: =G21 -> 53 | Q38: =P38/SUM($P$37:$P$39) -> 0.30813953
O39: B | P39: =H21 -> 12 | Q39: =P39/SUM($P$37:$P$39) -> 0.069767442

Sheet Mentor_Application
A2: Function Code | C2: MTR_APPLICATION | F2: Function Name | L2: =FunctionList!D11 -> See the per-case source map in the evidence document
A3: Created By | C3: Nguyen Bao Trung | F3: Executed By
A4: Lines of code | F4: Lack of test cases | L4: =IF(ISNUMBER(FunctionList!E6),MAX(0,ROUNDUP(C4*FunctionList!E6/1000,0)-O7),"N/A") -> 0
A5: Test requirement | C5: Register as Mentor and submit CV / qualification certificates [UC15]
A6: Passed | C6: Failed | F6: Untested | L6: N / A / B | O6: Total Test Cases
A7: =COUNTIF(F32:M32,"P") -> 8 | C7: =COUNTIF(F32:M32,"F") -> 0 | F7: =O7-A7-C7 -> 0 | L7: =COUNTIF(F31:M31,"N") -> 0 | M7: =COUNTIF(F31:M31,"A") -> 7 | N7: =COUNTIF(F31:M31,"B") -> 1 | O7: =COUNTA(F9:M9) -> 8
F9: UTCID01 | G9: UTCID02 | H9: UTCID03 | I9: UTCID04 | J9: UTCID05 | K9: UTCID06 | L9: UTCID07 | M9: UTCID08
A10: Condition | B10: Precondition
B11: Registered active account; no pending mentor application. Active skill exists; CV/certificates must be PDF files under 10 MB. | F11: O | G11: O | H11: O | I11: O | J11: O | K11: O | L11: O | M11: O | N11: O | O11: O
B12: MTC001: anonymous otp approval preserves both roles and private document | F12: O
B13: MTC002: existing mentee must login and cannot change account email | G13: O
B14: MTC003: otp cooldown attempt limit expiry and resend are enforced | H14: O
B15: MTC004: staff permission and rejection resubmission are enforced | I15: O
B16: MTC005: mail failure is not reported as submission success and invalid pdf is rejected | J16: O
B17: MTC006: google cannot provision or upgrade a mentor | K17: O
B18: MTC007: password can resume draft but cannot authenticate before otp | L18: O
B19: MTC008: self review and revoked reviewer are denied | M19: O
A21: Confirm | B21: Expected results
B22: Expected outcome is verified: Assertions hold: anonymous otp approval preserves both roles and private document. | F22: O
B23: Expected outcome is verified: Assertions hold: existing mentee must login and cannot change account email. | G23: O
B24: Expected outcome is verified: Assertions hold: otp cooldown attempt limit expiry and resend are enforced. | H24: O
B25: Expected outcome is verified: Assertions hold: staff permission and rejection resubmission are enforced. | I25: O
B26: Expected outcome is verified: Assertions hold: mail failure is not reported as submission success and invalid pdf is rejected. | J26: O
B27: Expected outcome is verified: Assertions hold: google cannot provision or upgrade a mentor. | K27: O
B28: Expected outcome is verified: Assertions hold: password can resume draft but cannot authenticate before otp. | L28: O
B29: Expected outcome is verified: Assertions hold: self review and revoked reviewer are denied. | M29: O
A31: Result | B31: Type (N / A / B) | F31: A | G31: A | H31: B | I31: A | J31: A | K31: A | L31: A | M31: A
B32: Passed / Failed | F32: P | G32: P | H32: P | I32: P | J32: P | K32: P | L32: P | M32: P
B33: Executed Date | F33: 2026-10-17 | G33: 2026-10-17 | H33: 2026-10-17 | I33: 2026-10-17 | J33: 2026-10-17 | K33: 2026-10-17 | L33: 2026-10-17 | M33: 2026-10-17
B34: Defect ID

Sheet Availability_Schedule
A2: Function Code | C2: MTR_AVAILABILITY | F2: Function Name | L2: =FunctionList!D12 -> See the per-case source map in the evidence document
A3: Created By | C3: Nguyen Bao Trung | F3: Executed By
A4: Lines of code | F4: Lack of test cases | L4: =IF(ISNUMBER(FunctionList!E6),MAX(0,ROUNDUP(C4*FunctionList!E6/1000,0)-O7),"N/A") -> 0
A5: Test requirement | C5: Publish availability and prevent conflicting slot reservations [No dedicated UC]
A6: Passed | C6: Failed | F6: Untested | L6: N / A / B | O6: Total Test Cases
A7: =COUNTIF(F60:AA60,"P") -> 22 | C7: =COUNTIF(F60:AA60,"F") -> 0 | F7: =O7-A7-C7 -> 0 | L7: =COUNTIF(F59:AA59,"N") -> 14 | M7: =COUNTIF(F59:AA59,"A") -> 7 | N7: =COUNTIF(F59:AA59,"B") -> 1 | O7: =COUNTA(F9:AA9) -> 22
F9: UTCID01 | G9: UTCID02 | H9: UTCID03 | I9: UTCID04 | J9: UTCID05 | K9: UTCID06 | L9: UTCID07 | M9: UTCID08 | N9: UTCID09 | O9: UTCID10 | P9: UTCID11 | Q9: UTCID12 | R9: UTCID13 | S9: UTCID14 | T9: UTCID15 | U9: UTCID16 | V9: UTCID17 | W9: UTCID18 | X9: UTCID19 | Y9: UTCID20 | Z9: UTCID21 | AA9: UTCID22
A10: Condition | B10: Precondition
B11: Authenticated active Mentor; valid future availability. Slot holds expire after 10 minutes and overlapping confirmed reservations are forbidden. | F11: O | G11: O | H11: O | I11: O | J11: O | K11: O | L11: O | M11: O | N11: O | O11: O | P11: O | Q11: O | R11: O | S11: O | T11: O | U11: O | V11: O | W11: O | X11: O | Y11: O | Z11: O | AA11: O
B12: MTC009: get my availability returns published slots | F12: O
B13: MTC010: create slot returns created | G13: O
B14: MTC011: create slot rejects missing start | H14: O
B15: MTC012: delete slot returns ok | I15: O
B16: MTC013: get mentor availability returns public slots | J16: O
B17: MTC014: hold slot returns created | K17: O
B18: MTC015: hold slot rejects missing fields | L18: O
B19: MTC016: release slot returns ok | M19: O
B20: MTC096: mentor publishes an open slot and sees it listed | N20: O
B21: MTC097: create slot rejects an overlapping slot | O21: O
B22: MTC098: create slot rejects end before start | P22: O
B23: MTC099: delete slot removes the mentors slot | Q23: O
B24: MTC100: hold rejects booking less than two hours ahead | R24: O
B25: MTC101: hold rejects time outside published availability | S25: O
B26: MTC102: mentee holds an open slot for ten minutes and it becomes unavailable | T26: O
B27: MTC103: second mentee cannot hold an overlapping slot | U27: O
B28: MTC104: release slot makes the slot available again | V28: O
B29: MTC105: delete slot rejects when the slot is booked | W29: O
B30: MTC160: availability module renders the open-slot manager | X30: O
B31: MTC162: getMyAvailability returns the slot list from the envelope | Y31: O
B32: MTC163: createSlot fetches a CSRF token before posting the slot | Z32: O
B33: MTC164: deleteSlot sends an authenticated CSRF delete request | AA33: O
A35: Confirm | B35: Expected results
B36: Expected outcome is verified: Assertions hold: get my availability returns published slots. | F36: O
B37: Expected outcome is verified: Assertions hold: create slot returns created. | G37: O
B38: Expected outcome is verified: Assertions hold: create slot rejects missing start. | H38: O
B39: Expected outcome is verified: Assertions hold: delete slot returns ok. | I39: O
B40: Expected outcome is verified: Assertions hold: get mentor availability returns public slots. | J40: O
B41: Expected outcome is verified: Assertions hold: hold slot returns created. | K41: O
B42: Expected outcome is verified: Assertions hold: hold slot rejects missing fields. | L42: O
B43: Expected outcome is verified: Assertions hold: release slot returns ok. | M43: O
...

Sheet Profile_Management
A2: Function Code | C2: MTR_PROFILE | F2: Function Name | L2: =FunctionList!D13 -> See the per-case source map in the evidence document
A3: Created By | C3: Nguyen Bao Trung | F3: Executed By
A4: Lines of code | F4: Lack of test cases | L4: =IF(ISNUMBER(FunctionList!E6),MAX(0,ROUNDUP(C4*FunctionList!E6/1000,0)-O7),"N/A") -> 0
A5: Test requirement | C5: Manage profile, biography, experience, links and teaching skills [UC13 / UC11]
A6: Passed | C6: Failed | F6: Untested | L6: N / A / B | O6: Total Test Cases
A7: =COUNTIF(F88:AO88,"P") -> 35 | C7: =COUNTIF(F88:AO88,"F") -> 0 | F7: =O7-A7-C7 -> 1 | L7: =COUNTIF(F87:AO87,"N") -> 22 | M7: =COUNTIF(F87:AO87,"A") -> 9 | N7: =COUNTIF(F87:AO87,"B") -> 5 | O7: =COUNTA(F9:AO9) -> 36
F9: UTCID01 | G9: UTCID02 | H9: UTCID03 | I9: UTCID04 | J9: UTCID05 | K9: UTCID06 | L9: UTCID07 | M9: UTCID08 | N9: UTCID09 | O9: UTCID10 | P9: UTCID11 | Q9: UTCID12 | R9: UTCID13 | S9: UTCID14 | T9: UTCID15 | U9: UTCID16 | V9: UTCID17 | W9: UTCID18 | X9: UTCID19 | Y9: UTCID20 | Z9: UTCID21 | AA9: UTCID22 | AB9: UTCID23 | AC9: UTCID24 | AD9: UTCID25 | AE9: UTCID26 | AF9: UTCID27 | AG9: UTCID28 | AH9: UTCID29 | AI9: UTCID30 | AJ9: UTCID31 | AK9: UTCID32 | AL9: UTCID33 | AM9: UTCID34 | AN9: UTCID35 | AO9: UTCID36
A10: Condition | B10: Precondition
B11: Authenticated active Mentor. Teaching-skill catalog is configured and only active skills can be selected. | F11: O | G11: O | H11: O | I11: O | J11: O | K11: O | L11: O | M11: O | N11: O | O11: O | P11: O | Q11: O | R11: O | S11: O | T11: O | U11: O | V11: O | W11: O | X11: O | Y11: O | Z11: O | AA11: O | AB11: O | AC11: O | AD11: O | AE11: O | AF11: O | AG11: O | AH11: O | AI11: O | AJ11: O | AK11: O | AL11: O | AM11: O | AN11: O | AO11: O
B12: MTC017: should return featured mentors | F12: O
B13: MTC018: should filter by keyword skill experience price and rating | G13: O
B14: MTC019: should return empty list when no mentor matches | H14: O
B15: MTC032: profile endpoints declare read and write transactions | I15: O
B16: MTC033: should preserve featured mentor response | J16: O
B17: MTC034: should return profile inside api response envelope | K17: O
B18: MTC035: should allow development frontend cors for profile and dashboard routes | L18: O
B19: MTC036: should return api response envelope when demo identity is disabled | M19: O
B20: MTC037: should validate profile update request | N20: O
B21: MTC038: should update profile through service and return envelope | O21: O
B22: MTC039: should return only active skill catalog response | P22: O
B23: MTC040: should reject inactive skill catalog request | Q23: O
B24: MTC071: mentor profile uses owning user id as primary key | R24: O
B25: MTC072: mentor skill uses embedded key and maps both relationships | S25: O
B26: MTC073: mentor skill id uses both keys for equality | T26: O
B27: MTC074: skill entity maps the active flag from the existing catalog table | U27: O
B28: MTC075: profile request rejects biography shorter than schema minimum | V28: O
B29: MTC076: profile request rejects biography whose trimmed length is below schema minimum | W29: O
B30: MTC077: profile request accepts valid profile data | X30: O
B31: MTC078: profile request rejects experience above schema limit | Y31: O
B32: MTC079: profile request rejects non http professional links | Z32: O
B33: MTC080: profile request requires at least one skill | AA33: O
B34: MTC081: get profile combines account profile and active skills | AB34: O
B35: MTC082: disabled demo identity fails before accessing repositories | AC35: O
B36: MTC083: missing demo user id fails closed | AD36: O
B37: MTC084: demo identity must belong to an active mentor | AE37: O
B38: MTC085: rejects invalid skill selection before changing profile fields | AF38: O
B39: MTC086: rejects duplicate skill ids before repository writes | AG39: O
B40: MTC087: lists only skills returned by active catalog query | AH40: O
B41: MTC088: updates profile and synchronizes only active skill links | AI41: O
B42: MTC094: active mentor skill query filters inactive catalog skills | AJ42: O
...

Sheet Package_Management
A2: Function Code | C2: MTR_PACKAGES | F2: Function Name | L2: =FunctionList!D14 -> See the per-case source map in the evidence document
A3: Created By | C3: Nguyen Bao Trung | F3: Executed By
A4: Lines of code | F4: Lack of test cases | L4: =IF(ISNUMBER(FunctionList!E6),MAX(0,ROUNDUP(C4*FunctionList!E6/1000,0)-O7),"N/A") -> 0
A5: Test requirement | C5: Manage mentor service offerings and selected package price [No dedicated UC]
A6: Passed | C6: Failed | F6: Untested | L6: N / A / B | O6: Total Test Cases
A7: =COUNTIF(F38:P38,"P") -> 11 | C7: =COUNTIF(F38:P38,"F") -> 0 | F7: =O7-A7-C7 -> 0 | L7: =COUNTIF(F37:P37,"N") -> 7 | M7: =COUNTIF(F37:P37,"A") -> 4 | N7: =COUNTIF(F37:P37,"B") -> 0 | O7: =COUNTA(F9:P9) -> 11
F9: UTCID01 | G9: UTCID02 | H9: UTCID03 | I9: UTCID04 | J9: UTCID05 | K9: UTCID06 | L9: UTCID07 | M9: UTCID08 | N9: UTCID09 | O9: UTCID10 | P9: UTCID11
A10: Condition | B10: Precondition
B11: Authenticated active Mentor with service-offering records; public selection is limited to active offerings. | F11: O | G11: O | H11: O | I11: O | J11: O | K11: O | L11: O | M11: O | N11: O | O11: O | P11: O
B12: MTC025: get my plans returns the standard envelope | F12: O
B13: MTC026: get mentor plans returns only active public packages | G13: O
B14: MTC027: get mentor offerings returns active public offerings | H14: O
B15: MTC028: save plans persists the tier set | I15: O
B16: MTC029: save plans rejects invalid tier payload | J16: O
B17: MTC030: storage failure returns generic retryable service error | K17: O
B18: MTC031: inactive mentor conflict is propagated | L18: O
B19: MTC139: selected offering id freezes that tier and its price | M19: O
B20: MTC140: does not guess when multiple packages exist and client omits selection | N20: O
B21: MTC141: rejects selected offering that is not active for the mentor | O21: O
B22: MTC161: packages module renders one card per tier with enable toggles | P22: O
A24: Confirm | B24: Expected results
B25: Expected outcome is verified: Assertions hold: get my plans returns the standard envelope. | F25: O
B26: Expected outcome is verified: Assertions hold: get mentor plans returns only active public packages. | G26: O
B27: Expected outcome is verified: Assertions hold: get mentor offerings returns active public offerings. | H27: O
B28: Expected outcome is verified: Assertions hold: save plans persists the tier set. | I28: O
B29: Expected outcome is verified: Assertions hold: save plans rejects invalid tier payload. | J29: O
B30: Expected outcome is verified: Assertions hold: storage failure returns generic retryable service error. | K30: O
B31: Expected outcome is verified: Assertions hold: inactive mentor conflict is propagated. | L31: O
B32: Expected outcome is verified: Assertions hold: selected offering id freezes that tier and its price. | M32: O
B33: Expected outcome is verified: Assertions hold: does not guess when multiple packages exist and client omits selection. | N33: O
B34: Expected outcome is verified: Assertions hold: rejects selected offering that is not active for the mentor. | O34: O
B35: Expected outcome is verified: Assertions hold: packages module renders one card per tier with enable toggles. | P35: O
A37: Result | B37: Type (N / A / B) | F37: N | G37: N | H37: N | I37: N | J37: A | K37: A | L37: A | M37: N | N37: N | O37: A | P37: N
B38: Passed / Failed | F38: P | G38: P | H38: P | I38: P | J38: P | K38: P | L38: P | M38: P | N38: P | O38: P | P38: P
B39: Executed Date | F39: 2026-10-17 | G39: 2026-10-17 | H39: 2026-10-17 | I39: 2026-10-17 | J39: 2026-10-17 | K39: 2026-10-17 | L39: 2026-10-17 | M39: 2026-10-17 | N39: 2026-10-17 | O39: 2026-10-17 | P39: 2026-10-17
B40: Defect ID

Sheet Dashboard_Overview
A2: Function Code | C2: MTR_DASHBOARD | F2: Function Name | L2: =FunctionList!D15 -> See the per-case source map in the evidence document
A3: Created By | C3: Nguyen Bao Trung | F3: Executed By
A4: Lines of code | F4: Lack of test cases | L4: =IF(ISNUMBER(FunctionList!E6),MAX(0,ROUNDUP(C4*FunctionList!E6/1000,0)-O7),"N/A") -> 0
A5: Test requirement | C5: View mentor request, notice, rating and earnings overview [No dedicated UC]
A6: Passed | C6: Failed | F6: Untested | L6: N / A / B | O6: Total Test Cases
A7: =COUNTIF(F42:R42,"P") -> 13 | C7: =COUNTIF(F42:R42,"F") -> 0 | F7: =O7-A7-C7 -> 0 | L7: =COUNTIF(F41:R41,"N") -> 10 | M7: =COUNTIF(F41:R41,"A") -> 3 | N7: =COUNTIF(F41:R41,"B") -> 0 | O7: =COUNTA(F9:R9) -> 13
F9: UTCID01 | G9: UTCID02 | H9: UTCID03 | I9: UTCID04 | J9: UTCID05 | K9: UTCID06 | L9: UTCID07 | M9: UTCID08 | N9: UTCID09 | O9: UTCID10 | P9: UTCID11 | Q9: UTCID12 | R9: UTCID13
A10: Condition | B10: Precondition
B11: Authenticated active Mentor; repository fixtures provide mentor-scoped request, notice, rating and earnings data. | F11: O | G11: O | H11: O | I11: O | J11: O | K11: O | L11: O | M11: O | N11: O | O11: O | P11: O | Q11: O | R11: O
B12: MTC020: dashboard returns the standard envelope and all sections | F12: O
B13: MTC023: dashboard data access failure returns generic retryable service error | G13: O
B14: MTC089: earnings query uses successful refunds and the per payment commission snapshot | H14: O
B15: MTC093: notice query is bounded and uses current refund state timestamps | I15: O
B16: MTC106: dashboard aggregates only server resolved mentor metrics and records | J16: O
B17: MTC111: dashboard does not suppress persistence failures | K17: O
B18: MTC113: disabled mentor identity fails before dashboard queries | L18: O
B19: MTC115: notice projection becomes utc current state summary | M19: O
B20: MTC150: formats VND earnings as whole dong without fractional decimals | N20: O
B21: MTC151: formats remaining SLA time against an injectable current time | O21: O
B22: MTC152: bounds long learning goal summaries and handles empty goals | P22: O
B23: MTC153: metric card escapes text that may originate in dashboard data | Q23: O
B24: MTC165: getMyDashboard reads the current mentor dashboard endpoint | R24: O
A26: Confirm | B26: Expected results
B27: Expected outcome is verified: Assertions hold: dashboard returns the standard envelope and all sections. | F27: O
B28: Expected outcome is verified: Assertions hold: dashboard data access failure returns generic retryable service error. | G28: O
B29: Expected outcome is verified: Assertions hold: earnings query uses successful refunds and the per payment commission snapshot. | H29: O
B30: Expected outcome is verified: Assertions hold: notice query is bounded and uses current refund state timestamps. | I30: O
B31: Expected outcome is verified: Assertions hold: dashboard aggregates only server resolved mentor metrics and records. | J31: O
B32: Expected outcome is verified: Assertions hold: dashboard does not suppress persistence failures. | K32: O
B33: Expected outcome is verified: Assertions hold: disabled mentor identity fails before dashboard queries. | L33: O
B34: Expected outcome is verified: Assertions hold: notice projection becomes utc current state summary. | M34: O
B35: Expected outcome is verified: Assertions hold: formats VND earnings as whole dong without fractional decimals. | N35: O
B36: Expected outcome is verified: Assertions hold: formats remaining SLA time against an injectable current time. | O36: O
B37: Expected outcome is verified: Assertions hold: bounds long learning goal summaries and handles empty goals. | P37: O
B38: Expected outcome is verified: Assertions hold: metric card escapes text that may originate in dashboard data. | Q38: O
B39: Expected outcome is verified: Assertions hold: getMyDashboard reads the current mentor dashboard endpoint. | R39: O
A41: Result | B41: Type (N / A / B) | F41: N | G41: A | H41: N | I41: N | J41: N | K41: A | L41: A | M41: N | N41: N | O41: N | P41: N | Q41: N | R41: N
B42: Passed / Failed | F42: P | G42: P | H42: P | I42: P | J42: P | K42: P | L42: P | M42: P | N42: P | O42: P | P42: P | Q42: P | R42: P
B43: Executed Date | F43: 2026-10-17 | G43: 2026-10-17 | H43: 2026-10-17 | I43: 2026-10-17 | J43: 2026-10-17 | K43: 2026-10-17 | L43: 2026-10-17 | M43: 2026-10-17 | N43: 2026-10-17 | O43: 2026-10-17 | P43: 2026-10-17 | Q43: 2026-10-17 | R43: 2026-10-17
B44: Defect ID

Sheet Request_Approval
A2: Function Code | C2: MTR_REQUESTS | F2: Function Name | L2: =FunctionList!D16 -> See the per-case source map in the evidence document
A3: Created By | C3: Nguyen Bao Trung | F3: Executed By
A4: Lines of code | F4: Lack of test cases | L4: =IF(ISNUMBER(FunctionList!E6),MAX(0,ROUNDUP(C4*FunctionList!E6/1000,0)-O7),"N/A") -> 0
A5: Test requirement | C5: View and accept or reject pending mentorship requests [UC26]
A6: Passed | C6: Failed | F6: Untested | L6: N / A / B | O6: Total Test Cases
A7: =COUNTIF(F82:AL82,"P") -> 31 | C7: =COUNTIF(F82:AL82,"F") -> 0 | F7: =O7-A7-C7 -> 2 | L7: =COUNTIF(F81:AL81,"N") -> 19 | M7: =COUNTIF(F81:AL81,"A") -> 13 | N7: =COUNTIF(F81:AL81,"B") -> 1 | O7: =COUNTA(F9:AL9) -> 33
F9: UTCID01 | G9: UTCID02 | H9: UTCID03 | I9: UTCID04 | J9: UTCID05 | K9: UTCID06 | L9: UTCID07 | M9: UTCID08 | N9: UTCID09 | O9: UTCID10 | P9: UTCID11 | Q9: UTCID12 | R9: UTCID13 | S9: UTCID14 | T9: UTCID15 | U9: UTCID16 | V9: UTCID17 | W9: UTCID18 | X9: UTCID19 | Y9: UTCID20 | Z9: UTCID21 | AA9: UTCID22 | AB9: UTCID23 | AC9: UTCID24 | AD9: UTCID25 | AE9: UTCID26 | AF9: UTCID27 | AG9: UTCID28 | AH9: UTCID29 | AI9: UTCID30 | AJ9: UTCID31 | AK9: UTCID32 | AL9: UTCID33
A10: Condition | B10: Precondition
B11: Authenticated Mentor owns the request; monthly request is PENDING and within the 48-hour response window. | F11: O | G11: O | H11: O | I11: O | J11: O | K11: O | L11: O | M11: O | N11: O | O11: O | P11: O | Q11: O | R11: O | S11: O | T11: O | U11: O | V11: O | W11: O | X11: O | Y11: O | Z11: O | AA11: O | AB11: O | AC11: O | AD11: O | AE11: O | AF11: O | AG11: O | AH11: O | AI11: O | AJ11: O | AK11: O | AL11: O
B12: MTC021: request decision accepts only validated decision values | F12: O
B13: MTC022: decision conflict does not expose ownership | G13: O
B14: MTC024: request decision rejects non positive path identifier | H14: O
B15: MTC051: create one off returns created and delegates to the service | I15: O
B16: MTC052: create one off rejects a short agenda | J16: O
B17: MTC053: create one off requires an offering id | K17: O
B18: MTC054: create one off rejects an invalid experience level | L18: O
B19: MTC055: create one off requires terms version | M19: O
B20: MTC056: creates request pending mentor decision | N20: O
B21: MTC057: rejects short learning goals | O21: O
B22: MTC058: rejects unknown experience level | P22: O
B23: MTC059: unpublished package conflict is propagated | Q23: O
B24: MTC060: anonymous request is rejected | R24: O
B25: MTC061: cancels an application | S25: O
B26: MTC062: loads checkout info for accepted request | T26: O
B27: MTC063: starts pending sepay checkout | U27: O
B28: MTC064: lists my applications with status filter and pagination | V28: O
B29: MTC091: pending request query scopes the mentor and pending state | W29: O
B30: MTC092: decision query is one owner and deadline guarded transition | X30: O
B31: MTC108: decision uses only configured identity and returns persisted decision | Y31: O
B32: MTC109: accepting a request notifies the mentee with payment next step | Z32: O
B33: MTC110: stale or foreign request decision returns opaque conflict without reloading | AA33: O
B34: MTC112: mentor request history returns persisted accepted and rejected rows | AB34: O
B35: MTC114: rejected decision returns the persisted state | AC35: O
B36: MTC116: accepts only an unexpired pending owned request without creating financial records | AD36: O
B37: MTC117: notice projection executes within mentor scope and returns at most ten rows | AE37: O
B38: MTC142: cancels owned accepted application without succeeded payment and notifies mentor | AF38: O
B39: MTC143: refuses cancellation when payment is succeeded | AG39: O
B40: MTC155: requests page exposes persisted request history, status filtering, and the shared details modal | AH40: O
B41: MTC166: getMyRequests reads persisted request history | AI41: O
B42: MTC167: decideOnRequest sends the decision with a CSRF header | AJ42: O
...

Sheet Workspace_Management
A2: Function Code | C2: MTR_WORKSPACE | F2: Function Name | L2: =FunctionList!D17 -> See the per-case source map in the evidence document
A3: Created By | C3: Nguyen Bao Trung | F3: Executed By
A4: Lines of code | F4: Lack of test cases | L4: =IF(ISNUMBER(FunctionList!E6),MAX(0,ROUNDUP(C4*FunctionList!E6/1000,0)-O7),"N/A") -> 0
A5: Test requirement | C5: Access active mentorship workspace, messages and files [UC32–33]
A6: Passed | C6: Failed | F6: Untested | L6: N / A / B | O6: Total Test Cases
A7: =COUNTIF(F44:S44,"P") -> 13 | C7: =COUNTIF(F44:S44,"F") -> 0 | F7: =O7-A7-C7 -> 1 | L7: =COUNTIF(F43:S43,"N") -> 10 | M7: =COUNTIF(F43:S43,"A") -> 3 | N7: =COUNTIF(F43:S43,"B") -> 1 | O7: =COUNTA(F9:S9) -> 14
F9: UTCID01 | G9: UTCID02 | H9: UTCID03 | I9: UTCID04 | J9: UTCID05 | K9: UTCID06 | L9: UTCID07 | M9: UTCID08 | N9: UTCID09 | O9: UTCID10 | P9: UTCID11 | Q9: UTCID12 | R9: UTCID13 | S9: UTCID14
A10: Condition | B10: Precondition
B11: Authenticated member of a paid active mentorship or confirmed booking; access is scoped to workspace membership. | F11: O | G11: O | H11: O | I11: O | J11: O | K11: O | L11: O | M11: O | N11: O | O11: O | P11: O | Q11: O | R11: O | S11: O
B12: MTC065: lists active workspaces | F12: O
B13: MTC066: sends validated message | G13: O
B14: MTC067: rejects blank message | H14: O
B15: MTC068: uploads workspace file | I15: O
B16: MTC069: downloads authorized workspace file as attachment | J16: O
B17: MTC070: marks workspace messages as read | K17: O
B18: MTC095: counts and marks unread messages for only the selected member | L18: O
B19: MTC144: lists only rows returned for current member | M19: O
B20: MTC145: rejects an authenticated non member | N20: O
B21: MTC146: repeated client key returns existing message without another insert | O21: O
B22: MTC147: uploads supported file into the member conversation | P22: O
B23: MTC148: rejects executable workspace file | Q23: O
B24: MTC149: marks only the current members conversation as read | R24: O
B25: MTC159: all mentor workspace routes share the operational shell and select their own navigation item | S25: O
A27: Confirm | B27: Expected results
B28: Expected outcome is verified: Assertions hold: lists active workspaces. | F28: O
B29: Expected outcome is verified: Assertions hold: sends validated message. | G29: O
B30: Expected outcome is verified: Assertions hold: rejects blank message. | H30: O
B31: Expected outcome is verified: Assertions hold: uploads workspace file. | I31: O
B32: Expected outcome is verified: Assertions hold: downloads authorized workspace file as attachment. | J32: O
B33: Expected outcome is verified: Assertions hold: marks workspace messages as read. | K33: O
B34: Expected outcome is verified: Skipped: conditional integration test (repository DB gate) - not executed. | L34: O
B35: Expected outcome is verified: Assertions hold: lists only rows returned for current member. | M35: O
B36: Expected outcome is verified: Assertions hold: rejects an authenticated non member. | N36: O
B37: Expected outcome is verified: Assertions hold: repeated client key returns existing message without another insert. | O37: O
B38: Expected outcome is verified: Assertions hold: uploads supported file into the member conversation. | P38: O
B39: Expected outcome is verified: Assertions hold: rejects executable workspace file. | Q39: O
B40: Expected outcome is verified: Assertions hold: marks only the current members conversation as read. | R40: O
B41: Expected outcome is verified: Assertions hold: all mentor workspace routes share the operational shell and select their own navigation item. | S41: O
A43: Result | B43: Type (N / A / B) | F43: N | G43: N | H43: A | I43: N | J43: N | K43: N | L43: N | M43: N | N43: A | O43: B | P43: N | Q43: A | R43: N | S43: N
B44: Passed / Failed | F44: P | G44: P | H44: P | I44: P | J44: P | K44: P | L44: U | M44: P | N44: P | O44: P | P44: P | Q44: P | R44: P | S44: P
...

Sheet Wallet_Payout
A2: Function Code | C2: MTR_WALLET | F2: Function Name | L2: =FunctionList!D18 -> See the per-case source map in the evidence document
A3: Created By | C3: Nguyen Bao Trung | F3: Executed By
A4: Lines of code | F4: Lack of test cases | L4: =IF(ISNUMBER(FunctionList!E6),MAX(0,ROUNDUP(C4*FunctionList!E6/1000,0)-O7),"N/A") -> 0
A5: Test requirement | C5: Review wallet and request OTP-protected payout [No dedicated UC]
A6: Passed | C6: Failed | F6: Untested | L6: N / A / B | O6: Total Test Cases
A7: =COUNTIF(F60:AA60,"P") -> 22 | C7: =COUNTIF(F60:AA60,"F") -> 0 | F7: =O7-A7-C7 -> 0 | L7: =COUNTIF(F59:AA59,"N") -> 16 | M7: =COUNTIF(F59:AA59,"A") -> 6 | N7: =COUNTIF(F59:AA59,"B") -> 0 | O7: =COUNTA(F9:AA9) -> 22
F9: UTCID01 | G9: UTCID02 | H9: UTCID03 | I9: UTCID04 | J9: UTCID05 | K9: UTCID06 | L9: UTCID07 | M9: UTCID08 | N9: UTCID09 | O9: UTCID10 | P9: UTCID11 | Q9: UTCID12 | R9: UTCID13 | S9: UTCID14 | T9: UTCID15 | U9: UTCID16 | V9: UTCID17 | W9: UTCID18 | X9: UTCID19 | Y9: UTCID20 | Z9: UTCID21 | AA9: UTCID22
A10: Condition | B10: Precondition
B11: Authenticated Mentor; verified earnings respect the seven-day hold; bank destination and valid OTP are required for withdrawal. | F11: O | G11: O | H11: O | I11: O | J11: O | K11: O | L11: O | M11: O | N11: O | O11: O | P11: O | Q11: O | R11: O | S11: O | T11: O | U11: O | V11: O | W11: O | X11: O | Y11: O | Z11: O | AA11: O
B12: MTC044: get bank account returns the saved destination | F12: O
B13: MTC045: save bank account persists the destination | G13: O
B14: MTC046: save bank account rejects an invalid account number | H14: O
B15: MTC047: request payout otp sends a code | I15: O
B16: MTC048: submit payout delegates to the otp gated service | J16: O
B17: MTC049: submit payout rejects a malformed otp | K17: O
B18: MTC050: insufficient balance conflict is propagated | L18: O
B19: MTC118: save bank account encrypts the number and masks it on read | M19: O
B20: MTC119: bank account is empty before the mentor saves one | N20: O
B21: MTC120: request payout otp requires a saved bank account | O21: O
B22: MTC121: submit payout requires a saved bank account | P22: O
B23: MTC122: submit payout rejects when no code was ever requested | Q23: O
B24: MTC123: submit payout rejects an invalid code | R24: O
B25: MTC124: submit payout verifies the code before enforcing the available balance | S25: O
B26: MTC134: splits gross payment using saved commission and whole vnd rounding | T26: O
B27: MTC135: rounds fractional commission once and preserves gross total | U27: O
B28: MTC136: payout account encryption uses authenticated ciphertext and random nonce | V28: O
B29: MTC137: payout details fail closed without configured encryption key | W29: O
B30: MTC138: masks mentor email before echoing it to the client | X30: O
B31: MTC156: mentor wallet page explains the hold, available funds and payout flow | Y31: O
B32: MTC157: mentor wallet page exposes saved bank account management and OTP verification | Z32: O
B33: MTC172: payout request fetches a CSRF token before posting bank details | AA33: O
A35: Confirm | B35: Expected results
B36: Expected outcome is verified: Assertions hold: get bank account returns the saved destination. | F36: O
B37: Expected outcome is verified: Assertions hold: save bank account persists the destination. | G37: O
B38: Expected outcome is verified: Assertions hold: save bank account rejects an invalid account number. | H38: O
B39: Expected outcome is verified: Assertions hold: request payout otp sends a code. | I39: O
B40: Expected outcome is verified: Assertions hold: submit payout delegates to the otp gated service. | J40: O
B41: Expected outcome is verified: Assertions hold: submit payout rejects a malformed otp. | K41: O
B42: Expected outcome is verified: Assertions hold: insufficient balance conflict is propagated. | L42: O
B43: Expected outcome is verified: Assertions hold: save bank account encrypts the number and masks it on read. | M43: O
...

Sheet Review_Feedback
A2: Function Code | C2: MTR_REVIEWS | F2: Function Name | L2: =FunctionList!D19 -> See the per-case source map in the evidence document
A3: Created By | C3: Nguyen Bao Trung | F3: Executed By
A4: Lines of code | F4: Lack of test cases | L4: =IF(ISNUMBER(FunctionList!E6),MAX(0,ROUNDUP(C4*FunctionList!E6/1000,0)-O7),"N/A") -> 0
A5: Test requirement | C5: View net earnings, rating summary and mentee feedback [UC28 / UC35]
A6: Passed | C6: Failed | F6: Untested | L6: N / A / B | O6: Total Test Cases
A7: =COUNTIF(F42:R42,"P") -> 13 | C7: =COUNTIF(F42:R42,"F") -> 0 | F7: =O7-A7-C7 -> 0 | L7: =COUNTIF(F41:R41,"N") -> 9 | M7: =COUNTIF(F41:R41,"A") -> 1 | N7: =COUNTIF(F41:R41,"B") -> 3 | O7: =COUNTA(F9:R9) -> 13
F9: UTCID01 | G9: UTCID02 | H9: UTCID03 | I9: UTCID04 | J9: UTCID05 | K9: UTCID06 | L9: UTCID07 | M9: UTCID08 | N9: UTCID09 | O9: UTCID10 | P9: UTCID11 | Q9: UTCID12 | R9: UTCID13
A10: Condition | B10: Precondition
B11: Authenticated Mentor with active profile; reviews are eligible/published and feedback is limited to completed bookings. | F11: O | G11: O | H11: O | I11: O | J11: O | K11: O | L11: O | M11: O | N11: O | O11: O | P11: O | Q11: O | R11: O
B12: MTC041: get my reviews returns summary and cards | F12: O
B13: MTC042: get my reviews uses default paging | G13: O
B14: MTC043: get my reviews honors paging params | H14: O
B15: MTC090: rating query excludes hidden and flagged reviews | I15: O
B16: MTC107: empty dashboard uses zero earnings and an explicit missing rating value | J16: O
B17: MTC126: returns summary and current page | K17: O
B18: MTC127: clamps negative page and default size | L18: O
B19: MTC128: caps page size at maximum | M19: O
B20: MTC129: returns empty summary without querying items when no reviews | N20: O
B21: MTC130: returns empty items when page is beyond total | O21: O
B22: MTC158: mentor wallet page renders the read-only mentee feedback section | P22: O
B23: MTC170: getMyReviews requests the paged mentor review endpoint and normalizes the payload | Q23: O
B24: MTC171: getMyReviews defaults to page 0 and size 10 and tolerates an empty response | R24: O
A26: Confirm | B26: Expected results
B27: Expected outcome is verified: Assertions hold: get my reviews returns summary and cards. | F27: O
B28: Expected outcome is verified: Assertions hold: get my reviews uses default paging. | G28: O
B29: Expected outcome is verified: Assertions hold: get my reviews honors paging params. | H29: O
B30: Expected outcome is verified: Assertions hold: rating query excludes hidden and flagged reviews. | I30: O
B31: Expected outcome is verified: Assertions hold: empty dashboard uses zero earnings and an explicit missing rating value. | J31: O
B32: Expected outcome is verified: Assertions hold: returns summary and current page. | K32: O
B33: Expected outcome is verified: Assertions hold: clamps negative page and default size. | L33: O
B34: Expected outcome is verified: Assertions hold: caps page size at maximum. | M34: O
B35: Expected outcome is verified: Assertions hold: returns empty summary without querying items when no reviews. | N35: O
B36: Expected outcome is verified: Assertions hold: returns empty items when page is beyond total. | O36: O
B37: Expected outcome is verified: Assertions hold: mentor wallet page renders the read-only mentee feedback section. | P37: O
B38: Expected outcome is verified: Assertions hold: getMyReviews requests the paged mentor review endpoint and normalizes the payload. | Q38: O
B39: Expected outcome is verified: Assertions hold: getMyReviews defaults to page 0 and size 10 and tolerates an empty response. | R39: O
A41: Result | B41: Type (N / A / B) | F41: N | G41: N | H41: N | I41: N | J41: A | K41: N | L41: B | M41: B | N41: N | O41: B | P41: N | Q41: N | R41: N
B42: Passed / Failed | F42: P | G42: P | H42: P | I42: P | J42: P | K42: P | L42: P | M42: P | N42: P | O42: P | P42: P | Q42: P | R42: P
B43: Executed Date | F43: 2026-10-17 | G43: 2026-10-17 | H43: 2026-10-17 | I43: 2026-10-17 | J43: 2026-10-17 | K43: 2026-10-17 | L43: 2026-10-17 | M43: 2026-10-17 | N43: 2026-10-17 | O43: 2026-10-17 | P43: 2026-10-17 | Q43: 2026-10-17 | R43: 2026-10-17
B44: Defect ID
